import os
import shutil
import subprocess
from pathlib import Path

import pytest
from typer.testing import CliRunner

from atopile import errors
from atopile.cli.build import _init_python_app
from atopile.cli.common import create_build_contexts

runner = CliRunner(mix_stderr=False)

PROJECT_DIR = Path("test/common/resources/test-project")


@pytest.fixture()
def from_project_dir(tmp_path: Path, monkeypatch: pytest.MonkeyPatch):
    tmp_project_dir = tmp_path / "test-project"
    shutil.copytree(PROJECT_DIR, tmp_project_dir)
    monkeypatch.chdir(tmp_project_dir)

    yield

    shutil.rmtree(tmp_project_dir)
    monkeypatch.undo()


@pytest.mark.parametrize(
    "build_name,expected_error",
    [
        ("unconstructable", errors.UserPythonConstructionError),
        ("unimportable", errors.UserPythonModuleError),
    ],
)
@pytest.mark.usefixtures("from_project_dir")
def test_build_errors(build_name: str, expected_error):
    build_ctxs = create_build_contexts(
        entry=None, build=[build_name], target=[], option=[]
    )

    (build_ctx,) = build_ctxs

    with pytest.raises(expected_error) as exc_info:
        _init_python_app(build_ctx)

    assert exc_info.value.__cause__ is not None
    assert isinstance(exc_info.value.__cause__, ValueError)
    assert exc_info.value.__cause__.args == (build_name,)


@pytest.mark.parametrize("build_name", ["unconstructable", "unimportable"])
@pytest.mark.usefixtures("from_project_dir")
def test_build_error_logging(build_name: str):
    # CLIRunner doesn't give us the fully-formatted log output as seen by the user

    process = subprocess.Popen(
        ["ato", "build", "-b", build_name],
        stdout=subprocess.PIPE,
        stderr=subprocess.PIPE,
        text=True,
        env=os.environ.copy(),
    )

    stdout, stderr = process.communicate()

    # single error
    assert stdout.count("ERROR") == 1

    # single traceback
    assert stdout.count("‚ù±") == 1
    assert stdout.count("Traceback (most recent call last)") == 1
    assert "another exception occurred" not in stdout
    assert "direct cause of the following exception" not in stdout

    # including the test exception
    assert f'raise ValueError("{build_name}")' in stdout

    # exiting cleanly
    assert stdout.strip().endswith(
        "Unfortunately errors ^^^ stopped the build. If you need a hand jump on Discord! \nhttps://discord.gg/mjtxARsr9V üëã"
    )

    # exception groups are unwrapped
    assert "ExceptionGroup" not in stdout

    # with a non-zero exit code
    assert process.returncode == 1
